Workbook
Name _Hlk99456938: 'Línea Base'!$A$9

Sheet Datos de la Unidad Productiva
A4: FORMATO DE DIAGNÓSTICO EMPRESARIAL Y LÍNEA BASE DATOS GENERALES DEL PROYECTO
A7: Nombre del Emprendedor:
A8: Número de cédula del emprendedor:
A10: Nombre de la Iniciativa de Negocio:
A11: Sector Económico (según código CIIU):
A12: Tipo de iniciativa: | B12: Individual | D12: Familiar | F12: Asociativa
A13: Tiempo real de funcionamiento:
A14: Cantidad de empleados:
A15: Dirección de la UP:
A16: Teléfono fijo o celular:
A17: Correo electrónico:
A18: Redes sociales o página web (si aplica):
A19: Pertenece a un grupo étnico: | B19: Afro | C19: Indígena | D19: Raizal | E19: Ninguno | F19: Otro
A20: El tipo de vivienda es: | B20: Propia | D20: Familiar | F20: Arrendada
A21: Estrato socioeconómico: | B21: 1 | C21: 2 | D21: 3 | E21: 4 | F21: 5 | G21: 6
A23: Nombre del Dinamizador:
A24: Regional:
A25: De acuerdo con la Ley 1581 de 2012 Por la cual se dictan disposiciones generales para la protección de datos personales, el tratamiento de la información solicitada anteriormente es para uso exclusivo del Servicio Nacional de Aprendizaje SENA, en ningún momento será suministrada a terceros, por tal motivo, como emprendedor, autorizo el uso de la información para uso exclusivo de la Agencia Pública de Empleo SENA para los fines de emprendimiento y, en señal de aceptación firmo el presente documento, así como el anexo 1 línea base del diagnóstico empresarial".
A37: Firma del emprendedor

Sheet Diagnóstico
A2: FORMATO DE DIAGNÓSTICO EMPRESARIAL
A3: Agencia Pública de Empleo
A4: Nombre de la Unidad Productiva:
A5: Nombre del Emprendedor:
A6: Regional:
A7: Nombre del Dinamizador
A8: Fecha de aplicación de la Herramienta de Diagnóstico: | B8: _____ /_______ / _____
A10: INFORMACIÓN LEGAL Y ADMINISTRATIVA | B10: Rango Evaluativo | C10: Equivalencia Estado de Desarrollo | D10: Equivalencia porcentual
A11: 1. ¿Para la planeación estratégica y fijación de objetivos se tiene en cuenta al cliente interno y las tendencias del mercado? | C11: =IF(B11="","",IF(B11=0,$C$60,IF(B11=1,$C$61,IF(B11=2,$C$62)))) | D11: =IF(B11="","",IF(B11=0,$D$60,IF(B11=1,$D$61,IF(B11=2,$D$62))))
A12: 2. ¿Es suficiente el número de trabajadores para el cumplimiento de las actividades diarias de la empresa? | C12: =IF(B12="","",IF(B12=0,$C$60,IF(B12=1,$C$61,IF(B12=2,$C$62)))) | D12: =IF(B12="","",IF(B12=0,$D$60,IF(B12=1,$D$61,IF(B12=2,$D$62))))
A13: 3. ¿Cuenta con reemplazos en los momentos de ausencia prolongada de algún trabajador? | C13: =IF(B13="","",IF(B13=0,$C$60,IF(B13=1,$C$61,IF(B13=2,$C$62)))) | D13: =IF(B13="","",IF(B13=0,$D$60,IF(B13=1,$D$61,IF(B13=2,$D$62))))
A14: 4. ¿La Unidad Productiva se encuentra bancarizada para la gestión de ventas? | C14: =IF(B14="","",IF(B14=0,$C$60,IF(B14=1,$C$61,IF(B14=2,$C$62)))) | D14: =IF(B14="","",IF(B14=0,$D$60,IF(B14=1,$D$61,IF(B14=2,$D$62))))
A15: 5. ¿El emprendedor cuenta con la asignación de salario? | C15: =IF(B15="","",IF(B15=0,$C$60,IF(B15=1,$C$61,IF(B15=2,$C$62)))) | D15: =IF(B15="","",IF(B15=0,$D$60,IF(B15=1,$D$61,IF(B15=2,$D$62))))
A16: 6. ¿El emprendedor y sus empleados (si aplica) se encuentran afiliados a un sistema de seguridad social contributivo? | C16: =IF(B16="","",IF(B16=0,$C$60,IF(B16=1,$C$61,IF(B16=2,$C$62)))) | D16: =IF(B16="","",IF(B16=0,$D$60,IF(B16=1,$D$61,IF(B16=2,$D$62))))
A17: 7. ¿Tiene una estructura organizacional definida e implementada? (Organigrama, manual de funciones y definición de perfiles) | C17: =IF(B17="","",IF(B17=0,$C$60,IF(B17=1,$C$61,IF(B17=2,$C$62)))) | D17: =IF(B17="","",IF(B17=0,$D$60,IF(B17=1,$D$61,IF(B17=2,$D$62))))
A18: 8. Seguridad y Salud en el trabajo: ¿Identifica y utiliza apropiadamente los elementos de protección personal y la Unidad Productiva está señalizada? | C18: =IF(B18="","",IF(B18=0,$C$60,IF(B18=1,$C$61,IF(B18=2,$C$62)))) | D18: =IF(B18="","",IF(B18=0,$D$60,IF(B18=1,$D$61,IF(B18=2,$D$62))))
A19: 9. ¿Su unidad productiva ha implmentado herramientas de innovación para mejorar competitivamente? | C19: =IF(B19="","",IF(B19=0,$C$60,IF(B19=1,$C$61,IF(B19=2,$C$62)))) | D19: =IF(B19="","",IF(B19=0,$D$60,IF(B19=1,$D$61,IF(B19=2,$D$62))))
A20: 10. ¿Conoce los permisos y licencias que requiere el funcionamiento de su unidad productiva, además, está comprometida con el cuidado y preservación del medio ambiente? | C20: =IF(B20="","",IF(B20=0,$C$60,IF(B20=1,$C$61,IF(B20=2,$C$62)))) | D20: =IF(B20="","",IF(B20=0,$D$60,IF(B20=1,$D$61,IF(B20=2,$D$62))))
A21: TOTAL ÁREA | B21: =SUM(B11:B20) -> 0 | D21: =SUM(D11:D20) -> 0
A22: INFORMACIÓN COMERCIAL | B22: Rango Evaluativo | C22: Equivalencia Estado de Desarrollo | D22: Equivalencia porcentual
A23: 1. ¿Qué productos o servicios ofrece la unidad productiva al mercado? (Todos) | C23: =IF(B23="","",IF(B23=0,$C$60,IF(B23=1,$C$61,IF(B23=2,$C$62)))) | D23: =IF(B23="","",IF(B23=0,$D$60,IF(B23=1,$D$61,IF(B23=2,$D$62))))
A24: 2. ¿Conoce la participación de cada producto / servicio en el total de ventas de la empresa? | C24: =IF(B24="","",IF(B24=0,$C$60,IF(B24=1,$C$61,IF(B24=2,$C$62)))) | D24: =IF(B24="","",IF(B24=0,$D$60,IF(B24=1,$D$61,IF(B24=2,$D$62))))
A25: 3. ¿En qué se fundamenta para hacer cambios en los productos o servicios? | C25: =IF(B25="","",IF(B25=0,$C$60,IF(B25=1,$C$61,IF(B25=2,$C$62)))) | D25: =IF(B25="","",IF(B25=0,$D$60,IF(B25=1,$D$61,IF(B25=2,$D$62))))
A26: 4. ¿Cómo define el componente diferenciador de su producto o servicio frente a la competencia? | C26: =IF(B26="","",IF(B26=0,$C$60,IF(B26=1,$C$61,IF(B26=2,$C$62)))) | D26: =IF(B26="","",IF(B26=0,$D$60,IF(B26=1,$D$61,IF(B26=2,$D$62))))
A27: 5. ¿Tiene identificado y caracterizado a su cliente objetivo y potencial? | C27: =IF(B27="","",IF(B27=0,$C$60,IF(B27=1,$C$61,IF(B27=2,$C$62)))) | D27: =IF(B27="","",IF(B27=0,$D$60,IF(B27=1,$D$61,IF(B27=2,$D$62))))
A28: 6. ¿Investiga tendencias del sector y de su producto o servicio a nivel nacional e internacional? | C28: =IF(B28="","",IF(B28=0,$C$60,IF(B28=1,$C$61,IF(B28=2,$C$62)))) | D28: =IF(B28="","",IF(B28=0,$D$60,IF(B28=1,$D$61,IF(B28=2,$D$62))))
A29: 7. ¿Su unidad productiva tiene en cuenta en sus procesos las características / análisis de la competencia? (Precio, calidad, fortalezas, debilidades) | C29: =IF(B29="","",IF(B29=0,$C$60,IF(B29=1,$C$61,IF(B29=2,$C$62)))) | D29: =IF(B29="","",IF(B29=0,$D$60,IF(B29=1,$D$61,IF(B29=2,$D$62))))
A30: 8. ¿Tiene meta en ventas mensuales, hace seguimiento a su cumplimiento? | C30: =IF(B30="","",IF(B30=0,$C$60,IF(B30=1,$C$61,IF(B30=2,$C$62)))) | D30: =IF(B30="","",IF(B30=0,$D$60,IF(B30=1,$D$61,IF(B30=2,$D$62))))
A31: 9. ¿Cuenta con un catálogo o portafolio de productos / servicios? | C31: =IF(B31="","",IF(B31=0,$C$60,IF(B31=1,$C$61,IF(B31=2,$C$62)))) | D31: =IF(B31="","",IF(B31=0,$D$60,IF(B31=1,$D$61,IF(B31=2,$D$62))))
A32: 10. ¿Cuenta con un plan de fidelización para los clientes? | C32: =IF(B32="","",IF(B32=0,$C$60,IF(B32=1,$C$61,IF(B32=2,$C$62)))) | D32: =IF(B32="","",IF(B32=0,$D$60,IF(B32=1,$D$61,IF(B32=2,$D$62))))
A33: TOTAL ÁREA | B33: =SUM(B23:B32) -> 0 | D33: =SUM(D23:D32) -> 0
A34: INFORMACIÓN TÉCNICA - OPERATIVA | B34: Rango Evaluativo | C34: Equivalencia Estado de Desarrollo | D34: Equivalencia porcentual
A35: 1. ¿Identifica y cuantifica los riesgos de producción en los procesos que realiza la unidad productiva? | C35: =IF(B35="","",IF(B35=0,$C$60,IF(B35=1,$C$61,IF(B35=2,$C$62)))) | D35: =IF(B35="","",IF(B35=0,$D$60,IF(B35=1,$D$61,IF(B35=2,$D$62))))
A36: 2. ¿Existen fichas técnicas de las maquinas, equipos, productos / servicios de la unidad productiva? | C36: =IF(B36="","",IF(B36=0,$C$60,IF(B36=1,$C$61,IF(B36=2,$C$62)))) | D36: =IF(B36="","",IF(B36=0,$D$60,IF(B36=1,$D$61,IF(B36=2,$D$62))))
A37: 3. ¿Es la infraestructura física adecuada para el desarrollo de la actividad económica? | C37: =IF(B37="","",IF(B37=0,$C$60,IF(B37=1,$C$61,IF(B37=2,$C$62)))) | D37: =IF(B37="","",IF(B37=0,$D$60,IF(B37=1,$D$61,IF(B37=2,$D$62))))
A38: 4. ¿Los puestos de trabajo y maquinaria están distribuidos para optimizar los tiempos de cada proceso al interior de la empresa? | C38: =IF(B38="","",IF(B38=0,$C$60,IF(B38=1,$C$61,IF(B38=2,$C$62)))) | D38: =IF(B38="","",IF(B38=0,$D$60,IF(B38=1,$D$61,IF(B38=2,$D$62))))
A39: 5. ¿Ha querido replicar en su unidad productiva algún avance que su competencia realizó? | C39: =IF(B39="","",IF(B39=0,$C$60,IF(B39=1,$C$61,IF(B39=2,$C$62)))) | D39: =IF(B39="","",IF(B39=0,$D$60,IF(B39=1,$D$61,IF(B39=2,$D$62))))
A40: 6. ¿Cuál es el manejo que se le da a los residuos que genera la empresa? | C40: =IF(B40="","",IF(B40=0,$C$60,IF(B40=1,$C$61,IF(B40=2,$C$62)))) | D40: =IF(B40="","",IF(B40=0,$D$60,IF(B40=1,$D$61,IF(B40=2,$D$62))))
A41: 7. ¿El proceso de producción y/o prestación del servicio está definido? (etapas, actividades, tareas, tiempos, cantidades y puntos de control). | C41: =IF(B41="","",IF(B41=0,$C$60,IF(B41=1,$C$61,IF(B41=2,$C$62)))) | D41: =IF(B41="","",IF(B41=0,$D$60,IF(B41=1,$D$61,IF(B41=2,$D$62))))
A42: 8. ¿El producto es flexible y se puede adaptar rápidamente a las tendencias del mercado? | C42: =IF(B42="","",IF(B42=0,$C$60,IF(B42=1,$C$61,IF(B42=2,$C$62)))) | D42: =IF(B42="","",IF(B42=0,$D$60,IF(B42=1,$D$61,IF(B42=2,$D$62))))
...

Sheet Línea Base
B2: FORMATO DE DIAGNÓSTICO EMPRESARIAL LÍNEA BASE
A4: Nombre de la Unidad Productiva:
A5: Nombre del Emprendedor:
A6: Regional:
A7: Nombre del Dinamizador
A9: Indicador | C9: Descripción | D9: Línea Base | F9: Resultado | H9: Variación
D10: Valor | E10: Fecha | F10: Valor | G10: Fecha
A11: 1 | B11: Ventas | C11: Comparación nivel de ventas al momento diagnóstico vs al finalizar proceso de fortalecimiento | D11: 0 | E11: Día / Mes / Año | F11: 0 | G11: Día / Mes / Año | H11: =IFERROR(((F11-D11)/D11)," ")
A12: 2 | B12: Gastos Fijos | C12: Comparación gastos de la empresa al momento diagnóstico vs al finalizar proceso de fortalecimiento | D12: 0 | F12: 0 | H12: =IFERROR(((F12-D12)/D12)," ")
A13: 3 | B13: Empleos | C13: Comparación generación empleos directos formales al momento diagnóstico vs al finalizar proceso de fortalecimiento | D13: Cantidad | F13: Cantidad | H13: =IFERROR(((F13-D13)/D13)," ")
A15: De acuerdo con la Ley 1581 de 2012 Por la cual se dictan disposiciones generales para la protección de datos personales, el tratamiento de la información solicitada anteriormente es para uso exclusivo del Servicio Nacional de Aprendizaje SENA, en ningún momento será suministrada a terceros, por tal motivo, como emprendedor, autorizo el uso de la información para uso exclusivo de la Agencia Pública de Empleo SENA para los fines de emprendimiento".

Sheet Gráfica Consolidado General
B3: Gráfica General del Diagnóstico
B7: Área | C7: Porcentaje | D7: Estado de desarrollo
B8: Legal - Administrativa | C8: =Diagnóstico!D21 -> 0 | D8: =IF(C8="","",IF('Gráfica Consolidado General'!C8>=60%,Diagnóstico!$C$62,IF(C8>=20%,Diagnóstico!$C$61,Diagnóstico!$C$60))) -> Desarrollo Nulo
B9: Comercial | C9: =Diagnóstico!D33 -> 0 | D9: =IF(C9="","",IF('Gráfica Consolidado General'!C9>=60%,Diagnóstico!$C$62,IF(C9>=20%,Diagnóstico!$C$61,Diagnóstico!$C$60))) -> Desarrollo Nulo
B10: Técnico - Operativa | C10: =Diagnóstico!D45 -> 0 | D10: =IF(C10="","",IF('Gráfica Consolidado General'!C10>=60%,Diagnóstico!$C$62,IF(C10>=20%,Diagnóstico!$C$61,Diagnóstico!$C$60))) -> Desarrollo Nulo
B11: Financiera y Contable | C11: =Diagnóstico!D57 -> 0 | D11: =IF(C11="","",IF('Gráfica Consolidado General'!C11>=60%,Diagnóstico!$C$62,IF(C11>=20%,Diagnóstico!$C$61,Diagnóstico!$C$60))) -> Desarrollo Nulo
B12: =IF(C12="","",IF('Gráfica Consolidado General'!C12>=60%,Diagnóstico!$C$62,IF(C12>=20%,Diagnóstico!$C$61,Diagnóstico!$C$60)))
B13: PROMEDIO Estado de Desarrollo Unidad Productiva | C13: =AVERAGE(C8:C11) -> 0 | D13: =IF(C13="","",IF('Gráfica Consolidado General'!C13>=60%,Diagnóstico!$C$62,IF(C13>=20%,Diagnóstico!$C$61,Diagnóstico!$C$60))) -> Desarrollo Nulo

Sheet Graficas por área
B2: Gráficas por Área de la Unidad Productiva
B5: Gráficos según equivalencia porcentual | M5: Gráficos según rango de evaluación
