Workbook
Name ACTIVIDADES_ARTÍSTICAS_DE_ENTRETENIMIENTO_Y_RECREACIÓN: 'Sectores EP'!$R$2:$R$18
Name ACTIVIDADES_DE_ATENCIÓN_DE_LA_SALUD_HUMANA_Y_DE_ASISTENCIA_SOCIAL: 'Sectores EP'!$Q$2:$Q$13
Name ACTIVIDADES_DE_SERVICIOS_ADMINISTRATIVOS_Y_DE_APOYO: 'Sectores EP'!$N$2:$N$27
Name ACTIVIDADES_FINANCIERAS_Y_DE_SEGUROS: 'Sectores EP'!$K$2:$K$32
Name ACTIVIDADES_INMOBILIARIAS: 'Sectores EP'!$L$2:$L$3
Name ACTIVIDADES_PROFESIONALES_CIENTÍFICAS_Y_TÉCNICAS: 'Sectores EP'!$M$2:$M$15
Name ADMINISTRACIÓN_PÚBLICA_Y_DEFENSA_PLANES_DE_SEGURIDAD_SOCIAL_DE_AFILIACIÓN_OBLIGATORIA: 'Sectores EP'!$O$2:$O$11
Name AGRICULTURA_GANADERÍA_CAZA_SILVICULTURA_Y_PESCA: 'Sectores EP'!$A$2:$A$37
Name Agroindustria: 'Sectores EC'!$B$2:$B$22
Name Agropecuario: 'Sectores EC'!$A$2:$A$37
Name ALOJAMIENTO_Y_SERVICIOS_DE_COMIDA: 'Sectores EP'!$I$2:$I$16
Name Amazonas: 'Dep-Mun'!$A$2:$A$12
Name Antioquia: 'Dep-Mun'!$B$2:$B$126
Name Arauca: 'Dep-Mun'!$C$2:$C$8
Name Archipiélago_De_San_Andrés: 'Dep-Mun'!$D$2:$D$3
Name Artesanías: 'Sectores EC'!$C$2:$C$25
Name Artesanías: 'Sectores EP'!$C$24:$C$129
Name Atlántico: 'Dep-Mun'!$E$2:$E$24
Name Bogotá_D.C.: 'Dep-Mun'!$F$2
Name Bolívar: 'Dep-Mun'!$G$2:$G$47
Name Boyacá: 'Dep-Mun'!$H$2:$H$124
Name Caldas: 'Dep-Mun'!$I$2:$I$28
Name Caquetá: 'Dep-Mun'!$J$2:$J$17
Name Casanare: 'Dep-Mun'!$K$2:$K$20
Name Cauca: 'Dep-Mun'!$L$2:$L$43
Name Cesar: 'Dep-Mun'!$M$2:$M$26
Name Chocó: 'Dep-Mun'!$N$2:$N$32
Name COMERCIO_AL_POR_MAYOR_Y_AL_POR_MENOR_REPARACIÓN_DE_VEHÍCULOS_AUTOMOTORES_Y_MOTOCICLETAS: 'Sectores EP'!$G$2:$G$58
Name COMERCIO_EC: 'Sectores EC'!$F$2:$F$8
Name CONSTRUCCIÓN: 'Sectores EP'!$F$2:$F$13
Name Córdoba: 'Dep-Mun'!$O$2:$O$31
Name Cundinamarca: 'Dep-Mun'!$P$2:$P$117
Name DEPARTAMENTOS: '[1]Dep-Mun'!$A$1:$AG$1
Name DEPARTAMENTOS: 'Dep-Mun'!$A$1:$AG$1
Name DISTRIBUCIÓN_DE_AGUA_EVACUACIÓN_Y_TRATAMIENTO_DE_AGUAS_RESIDUALES_GESTIÓN_DE_DESECHOS_Y_ACTIVIDADES_DE_SANEAMIENTO_AMBIENTAL: 'Sectores EP'!$E$2:$E$9
Name ECONOMÍA_CAMPESINA: 'TIPO PN'!$A$9:$A$14
Name ECONOMÍA_POPULAR: 'TIPO PN'!$B$9:$B$27
Name EDUCACIÓN: 'Sectores EP'!$P$2:$P$17
Name EXPLOTACIÓN_DE_MINAS_Y_CANTERAS: 'Sectores EP'!$B$2:$B$18
Name Guainía: 'Dep-Mun'!$Q$2:$Q$9
Name Guaviare: 'Dep-Mun'!$R$2:$R$5
Name Huila: 'Dep-Mun'!$S$2:$S$38
Name INDUSTRIAS_MANUFACTURERAS: 'Sectores EP'!$C$2:$C$141
Name INFORMACIÓN_Y_COMUNICACIONES: 'Sectores EP'!$J$2:$J$24
Name La_Guajira: 'Dep-Mun'!$T$2:$T$16
Name Magdalena: 'Dep-Mun'!$U$2:$U$31
Name Medio_Ambiente: 'Sectores EC'!$E$2:$E$8
Name Meta: 'Dep-Mun'!$V$2:$V$30
Name Nariño: 'Dep-Mun'!$W$2:$W$65
Name Norte_De_Santander: 'Dep-Mun'!$X$2:$X$41
Name OTRAS_ACTIVIDADES_DE_SERVICIOS: 'Sectores EP'!$S$2:$S$18
Name Putumayo: 'Dep-Mun'!$Y$2:$Y$14
Name Quindío: 'Dep-Mun'!$Z$2:$Z$13
Name Risaralda: 'Dep-Mun'!$AA$2:$AA$15
Name Santander: 'Dep-Mun'!$AB$2:$AB$88
Name SECTORES: 'Sectores EC'!$A$1:$F$1
Name SECTORES: 'Sectores EP'!$A$1:$S$1
Name Sucre: 'Dep-Mun'!$AC$2:$AC$27
Name SUMINISTRO_DE_ELECTRICIDAD_GAS_VAPOR_Y_AIRE_ACONDICIONADO: 'Sectores EP'!$D$2:$D$7
Name TIPO_PN: 'TIPO PN'!$A$8:$B$8

Sheet Dep-Mun
A1: Amazonas | B1: Antioquia | C1: Arauca | D1: Archipiélago_De_San_Andrés | E1: Atlántico | F1: Bogotá_D.C. | G1: Bolívar | H1: Boyacá | I1: Caldas | J1: Caquetá | K1: Casanare | L1: Cauca | M1: Cesar | N1: Chocó | O1: Córdoba | P1: Cundinamarca | Q1: Guainía | R1: Guaviare | S1: Huila | T1: La_Guajira | U1: Magdalena | V1: Meta | W1: Nariño | X1: Norte_De_Santander | Y1: Putumayo | Z1: Quindío | AA1: Risaralda | AB1: Santander | AC1: Sucre | AD1: Tolima | AE1: Valle_Del_Cauca | AF1: Vaupés | AG1: Vichada
A2: El Encanto | B2: Medellín | C2: Arauca | D2: San Andrés | E2: Barranquilla | F2: Bogotá, D.C. | G2: Cartagena De Indias | H2: Tunja | I2: Manizales | J2: Florencia | K2: Yopal | L2: Popayán | M2: Valledupar | N2: Quibdó | O2: Montería | P2: Agua De Dios | Q2: San Felipe | R2: San José Del Guaviare | S2: Neiva | T2: Riohacha | U2: Santa Marta | V2: Villavicencio | W2: Pasto | X2: San José De Cúcuta | Y2: Mocoa | Z2: Armenia | AA2: Pereira | AB2: Bucaramanga | AC2: Sincelejo | AD2: Ibagué | AE2: Santiago De Cali | AF2: Pacoa | AG2: Puerto Carreño
A3: La Chorrera | B3: Abejorral | C3: Arauquita | D3: Providencia | E3: Baranoa | G3: Achí | H3: Almeida | I3: Aguadas | J3: Albania | K3: Aguazul | L3: Almaguer | M3: Aguachica | N3: Acandí | O3: Ayapel | P3: Albán | Q3: Puerto Colombia | R3: Calamar | S3: Acevedo | T3: Albania | U3: Algarrobo | V3: Acacías | W3: Albán | X3: Ábrego | Y3: Colón | Z3: Buenavista | AA3: Apía | AB3: Aguada | AC3: Buenavista | AD3: Alpujarra | AE3: Alcalá | AF3: Papunahua | AG3: La Primavera
A4: La Pedrera | B4: Abriaquí | C4: Cravo Norte | E4: Campo De La Cruz | G4: Altos Del Rosario | H4: Aquitania | I4: Anserma | J4: Belén De Los Andaquíes | K4: Chámeza | L4: Argelia | M4: Agustín Codazzi | N4: Alto Baudó | O4: Buenavista | P4: Anapoima | Q4: La Guadalupe | R4: El Retorno | S4: Agrado | T4: Barrancas | U4: Aracataca | V4: Barranca De Upía | W4: Aldana | X4: Arboledas | Y4: Orito | Z4: Calarcá | AA4: Balboa | AB4: Albania | AC4: Caimito | AD4: Alvarado | AE4: Andalucía | AF4: Yavaraté | AG4: Santa Rosalía
A5: La Victoria | B5: Alejandría | C5: Fortul | E5: Candelaria | G5: Arenal | H5: Arcabuco | I5: Aranzazu | J5: Cartagena Del Chairá | K5: Hato Corozal | L5: Balboa | M5: Astrea | N5: Atrato | O5: Canalete | P5: Anolaima | Q5: Cacahual | R5: Miraflores | S5: Aipe | T5: Dibulla | U5: Ariguaní | V5: Cabuyaro | W5: Ancuya | X5: Bochalema | Y5: Puerto Asís | Z5: Circasia | AA5: Belén De Umbría | AB5: Aratoca | AC5: Colosó | AD5: Ambalema | AE5: Ansermanuevo | AF5: Mitú | AG5: Cumaribo
A6: Mirití - Paraná | B6: Amagá | C6: Puerto Rondón | E6: Galapa | G6: Arjona | H6: Belén | I6: Belalcázar | J6: Curillo | K6: La Salina | L6: Bolívar | M6: Becerril | N6: Bagadó | O6: Cereté | P6: Arbeláez | Q6: Pana Pana | S6: Algeciras | T6: Distracción | U6: Cerro De San Antonio | V6: Castilla La Nueva | W6: Arboleda | X6: Bucarasica | Y6: Puerto Caicedo | Z6: Córdoba | AA6: Dosquebradas | AB6: Barbosa | AC6: Corozal | AD6: Anzoátegui | AE6: Argelia | AF6: Carurú
A7: Puerto Alegría | B7: Amalfi | C7: Saravena | E7: Juan De Acosta | G7: Arroyohondo | H7: Berbeo | I7: Chinchiná | J7: El Doncello | K7: Maní | L7: Buenos Aires | M7: Bosconia | N7: Bahía Solano | O7: Chimá | P7: Beltrán | Q7: Morichal | S7: Altamira | T7: El Molino | U7: Chivolo | V7: Cubarral | W7: Barbacoas | X7: Cácota | Y7: Puerto Guzmán | Z7: Filandia | AA7: Guática | AB7: Barichara | AC7: Coveñas | AD7: Armero | AE7: Bolívar | AF7: Taraira
A8: Puerto Arica | B8: Andes | C8: Tame | E8: Luruaco | G8: Barranco De Loba | H8: Betéitiva | I8: Filadelfia | J8: El Paujíl | K8: Monterrey | L8: Cajibío | M8: Chimichagua | N8: Bajo Baudó | O8: Chinú | P8: Bituima | Q8: Inírida | S8: Baraya | T8: Fonseca | U8: Ciénaga | V8: Cumaral | W8: Belén | X8: Cáchira | Y8: Puerto Leguízamo | Z8: Génova | AA8: La Celia | AB8: Barrancabermeja | AC8: Chalán | AD8: Ataco | AE8: Buenaventura
A9: Puerto Santander | B9: Angelópolis | E9: Malambo | G9: Calamar | H9: Boavita | I9: La Dorada | J9: La Montañita | K9: Nunchía | L9: Caldono | M9: Chiriguaná | N9: Bojayá | O9: Ciénaga De Oro | P9: Bojacá | Q9: Barrancominas | S9: Campoalegre | T9: Hatonuevo | U9: Concordia | V9: El Calvario | W9: Buesaco | X9: Chinácota | Y9: Sibundoy | Z9: La Tebaida | AA9: La Virginia | AB9: Betulia | AC9: El Roble | AD9: Cajamarca | AE9: Guadalajara De Buga
A10: Tarapacá | B10: Angostura | E10: Manatí | G10: Cantagallo | H10: Boyacá | I10: La Merced | J10: Milán | K10: Orocué | L10: Caloto | M10: Curumaní | N10: El Cantón Del San Pablo | O10: Cotorra | P10: Cabrera | S10: Colombia | T10: La Jagua Del Pilar | U10: El Banco | V10: El Castillo | W10: Colón | X10: Chitagá | Y10: San Francisco | Z10: Montenegro | AA10: Marsella | AB10: Bolívar | AC10: Galeras | AD10: Carmen De Apicalá | AE10: Bugalagrande
A11: Leticia | B11: Anorí | E11: Palmar De Varela | G11: Cicuco | H11: Briceño | I11: Manzanares | J11: Morelia | K11: Paz De Ariporo | L11: Corinto | M11: El Copey | N11: Carmen Del Darién | O11: La Apartada | P11: Cachipay | S11: Elías | T11: Maicao | U11: El Piñón | V11: El Dorado | W11: Consacá | X11: Convención | Y11: San Miguel | Z11: Pijao | AA11: Mistrató | AB11: Cabrera | AC11: Guaranda | AD11: Casabianca | AE11: Caicedonia
A12: Puerto Nariño | B12: Santa Fé De Antioquia | E12: Piojó | G12: Córdoba | H12: Buenavista | I12: Marmato | J12: Puerto Rico | K12: Pore | L12: El Tambo | M12: El Paso | N12: Cértegui | O12: Lorica | P12: Cajicá | S12: Garzón | T12: Manaure | U12: El Retén | V12: Fuente De Oro | W12: Contadero | X12: Cucutilla | Y12: Santiago | Z12: Quimbaya | AA12: Pueblo Rico | AB12: California | AC12: La Unión | AD12: Chaparral | AE12: Calima
B13: Anzá | E13: Polonuevo | G13: Clemencia | H13: Busbanzá | I13: Marquetalia | J13: San José Del Fragua | K13: Recetor | L13: Florencia | M13: Gamarra | N13: Condoto | O13: Los Córdobas | P13: Caparrapí | S13: Gigante | T13: San Juan Del Cesar | U13: Fundación | V13: Granada | W13: Córdoba | X13: Durania | Y13: Valle Del Guamuez | Z13: Salento | AA13: Quinchía | AB13: Capitanejo | AC13: Los Palmitos | AD13: Coello | AE13: Candelaria
B14: Apartadó | E14: Ponedera | G14: El Carmen De Bolívar | H14: Caldas | I14: Marulanda | J14: San Vicente Del Caguán | K14: Sabanalarga | L14: Guachené | M14: González | N14: El Carmen De Atrato | O14: Momil | P14: Cáqueza | S14: Guadalupe | T14: Uribia | U14: Guamal | V14: Guamal | W14: Cuaspud Carlosama | X14: El Carmen | Y14: Villagarzón | AA14: Santa Rosa De Cabal | AB14: Carcasí | AC14: Majagual | AD14: Coyaima | AE14: Cartago
B15: Arboletes | E15: Puerto Colombia | G15: El Guamo | H15: Campohermoso | I15: Neira | J15: Solano | K15: Sácama | L15: Guapi | M15: La Gloria | N15: El Litoral Del San Juan | O15: Montelíbano | P15: Carmen De Carupa | S15: Hobo | T15: Urumita | U15: Nueva Granada | V15: Mapiripán | W15: Cumbal | X15: El Tarra | AA15: Santuario | AB15: Cepitá | AC15: Morroa | AD15: Cunday | AE15: Dagua
B16: Argelia | E16: Repelón | G16: El Peñón | H16: Cerinza | I16: Norcasia | J16: Solita | K16: San Luis De Palenque | L16: Inzá | M16: La Jagua De Ibirico | N16: Istmina | O16: Moñitos | P16: Chaguaní | S16: Íquira | T16: Villanueva | U16: Pedraza | V16: Mesetas | W16: Cumbitara | X16: El Zulia | AB16: Cerrito | AC16: Ovejas | AD16: Dolores | AE16: El Águila
B17: Armenia | E17: Sabanagrande | G17: Hatillo De Loba | H17: Chinavita | I17: Pácora | J17: Valparaíso | K17: Támara | L17: Jambaló | M17: Manaure Balcón Del Cesar | N17: Juradó | O17: Planeta Rica | P17: Chía | S17: Isnos | U17: Pijiño Del Carmen | V17: La Macarena | W17: Chachagüí | X17: Gramalote | AB17: Charalá | AC17: Palmito | AD17: Espinal | AE17: El Cairo
B18: Barbosa | E18: Sabanalarga | G18: Magangué | H18: Chiquinquirá | I18: Palestina | K18: Tauramena | L18: La Sierra | M18: Pailitas | N18: Lloró | O18: Pueblo Nuevo | P18: Chipaque | S18: La Argentina | U18: Pivijay | V18: Uribe | W18: El Charco | X18: Hacarí | AB18: Charta | AC18: Sampués | AD18: Falan | AE18: El Cerrito
B19: Belmira | E19: Santa Lucía | G19: Mahates | H19: Chiscas | I19: Pensilvania | K19: Trinidad | L19: La Vega | M19: Pelaya | N19: Medio Atrato | O19: Puerto Escondido | P19: Choachí | S19: La Plata | U19: Plato | V19: Lejanías | W19: El Peñol | X19: Herrán | AB19: Chima | AC19: San Benito Abad | AD19: Flandes | AE19: El Dovio
B20: Bello | E20: Santo Tomás | G20: Margarita | H20: Chita | I20: Riosucio | K20: Villanueva | L20: López De Micay | M20: Pueblo Bello | N20: Medio Baudó | O20: Puerto Libertador | P20: Chocontá | S20: Nátaga | U20: Puebloviejo | V20: Puerto Concordia | W20: El Rosario | X20: Labateca | AB20: Chipatá | AC20: San Juan De Betulia | AD20: Fresno | AE20: Florida
B21: Betania | E21: Soledad | G21: María La Baja | H21: Chitaraque | I21: Risaralda | L21: Mercaderes | M21: Río De Oro | N21: Medio San Juan | O21: Purísima De La Concepción | P21: Cogua | S21: Oporapa | U21: Remolino | V21: Puerto Gaitán | W21: El Tablón De Gómez | X21: La Esperanza | AB21: Cimitarra | AC21: San Marcos | AD21: Guamo | AE21: Ginebra
B22: Betulia | E22: Suan | G22: Montecristo | H22: Chivatá | I22: Salamina | L22: Miranda | M22: La Paz | N22: Nóvita | O22: Sahagún | P22: Cota | S22: Paicol | U22: Sabanas De San Ángel | V22: Puerto López | W22: El Tambo | X22: La Playa | AB22: Concepción | AC22: San Onofre | AD22: Herveo | AE22: Guacarí
B23: Ciudad Bolívar | E23: Tubará | G23: Santa Cruz De Mompox | H23: Ciénega | I23: Samaná | L23: Morales | M23: San Alberto | N23: Nuevo Belén De Bajirá * | O23: San Andrés De Sotavento | P23: Cucunubá | S23: Palermo | U23: Salamina | V23: Puerto Lleras | W23: Funes | X23: Los Patios | AB23: Confines | AC23: San Pedro | AD23: Honda | AE23: Jamundí
B24: Briceño | E24: Usiacurí | G24: Morales | H24: Cómbita | I24: San José | L24: Padilla | M24: San Diego | N24: Nuquí | O24: San Antero | P24: El Colegio | S24: Palestina | U24: San Sebastián De Buenavista | V24: Puerto Rico | W24: Guachucal | X24: Lourdes | AB24: Contratación | AC24: San Luis De Sincé | AD24: Icononzo | AE24: La Cumbre
B25: Buriticá | G25: Norosí | H25: Coper | I25: Supía | L25: Páez | M25: San Martín | N25: Río Iró | O25: San Bernardo Del Viento | P25: El Peñón | S25: Pital | U25: San Zenón | V25: Restrepo | W25: Guaitarilla | X25: Mutiscua | AB25: Coromoro | AC25: Sucre | AD25: Lérida | AE25: La Unión
B26: Cáceres | G26: Pinillos | H26: Corrales | I26: Victoria | L26: Patía | M26: Tamalameque | N26: Río Quito | O26: San Carlos | P26: El Rosal | S26: Pitalito | U26: Santa Ana | V26: San Carlos De Guaroa | W26: Gualmatán | X26: Ocaña | AB26: Curití | AC26: Santiago De Tolú | AD26: Líbano | AE26: La Victoria
B27: Caicedo | G27: Regidor | H27: Covarachía | I27: Villamaría | L27: Piamonte | N27: Riosucio | O27: San José De Uré | P27: Facatativá | S27: Rivera | U27: Santa Bárbara De Pinto | V27: San Juan De Arama | W27: Iles | X27: Pamplona | AB27: El Carmen De Chucurí | AC27: San José De Toluviejo | AD27: San Sebastián De Mariquita | AE27: Obando
B28: Caldas | G28: Río Viejo | H28: Cubará | I28: Viterbo | L28: Piendamó - Tunía | N28: San José Del Palmar | O28: San Pelayo | P28: Fómeque | S28: Saladoblanco | U28: Sitionuevo | V28: San Juanito | W28: Imués | X28: Pamplonita | AB28: El Guacamayo | AD28: Melgar | AE28: Palmira
B29: Campamento | G29: San Cristóbal | H29: Cucaita | L29: Puerto Tejada | N29: Sipí | O29: Tierralta | P29: Fosca | S29: San Agustín | U29: Tenerife | V29: San Martín | W29: Ipiales | X29: Puerto Santander | AB29: El Peñón | AD29: Murillo | AE29: Pradera
B30: Cañasgordas | G30: San Estanislao | H30: Cuítiva | L30: Puracé | N30: Tadó | O30: Tuchín | P30: Funza | S30: Santa María | U30: Zapayán | V30: Vistahermosa | W30: La Cruz | X30: Ragonvalia | AB30: El Playón | AD30: Natagaima | AE30: Restrepo
B31: Caracolí | G31: San Fernando | H31: Chíquiza | L31: Rosas | N31: Unguía | O31: Valencia | P31: Fúquene | S31: Suaza | U31: Zona Bananera | W31: La Florida | X31: Salazar | AB31: Encino | AD31: Ortega | AE31: Riofrío
B32: Caramanta | G32: San Jacinto | H32: Chivor | L32: San Sebastián | N32: Unión Panamericana | P32: Fusagasugá | S32: Tarqui | W32: La Llanada | X32: San Calixto | AB32: Enciso | AD32: Palocabildo | AE32: Roldanillo
B33: Carepa | G33: San Jacinto Del Cauca | H33: Duitama | L33: Santander De Quilichao | P33: Gachalá | S33: Tesalia | W33: La Tola | X33: San Cayetano | AB33: Florián | AD33: Piedras | AE33: San Pedro
B34: El Carmen De Viboral | G34: San Juan Nepomuceno | H34: El Cocuy | L34: Santa Rosa | P34: Gachancipá | S34: Tello | W34: La Unión | X34: Santiago | AB34: Floridablanca | AD34: Planadas | AE34: Sevilla
B35: Carolina | G35: San Martín De Loba | H35: El Espino | L35: Silvia | P35: Gachetá | S35: Teruel | W35: Leiva | X35: Sardinata | AB35: Galán | AD35: Prado | AE35: Toro
B36: Caucasia | G36: San Pablo | H36: Firavitoba | L36: Sotará Paispamba | P36: Gama | S36: Timaná | W36: Linares | X36: Silos | AB36: Gámbita | AD36: Purificación | AE36: Trujillo
B37: Chigorodó | G37: Santa Catalina | H37: Floresta | L37: Suárez | P37: Girardot | S37: Villavieja | W37: Los Andes | X37: Teorama | AB37: Girón | AD37: Rioblanco | AE37: Tuluá
B38: Cisneros | G38: Santa Rosa | H38: Gachantivá | L38: Sucre | P38: Granada | S38: Yaguará | W38: Magüí | X38: Tibú | AB38: Guaca | AD38: Roncesvalles | AE38: Ulloa
B39: Cocorná | G39: Santa Rosa Del Sur | H39: Gámeza | L39: Timbío | P39: Guachetá | W39: Mallama | X39: Toledo | AB39: Guadalupe | AD39: Rovira | AE39: Versalles
B40: Concepción | G40: Simití | H40: Garagoa | L40: Timbiquí | P40: Guaduas | W40: Mosquera | X40: Villa Caro | AB40: Guapotá | AD40: Saldaña | AE40: Vijes
...

Sheet TIPO PN
A2: TIPO_PN
A3: ECONOMÍA_CAMPESINA
A4: ECONOMÍA_POPULAR
A8: ECONOMÍA_CAMPESINA | B8: ECONOMÍA_POPULAR
A9: AGROPECUARIO | B9: AGRICULTURA_GANADERÍA_CAZA_SILVICULTURA_Y_PESCA
A10: AGROINDUSTRIA | B10: EXPLOTACIÓN_DE_MINAS_Y_CANTERAS
A11: ARTESANÍAS | B11: INDUSTRIAS_MANUFACTURERAS
A12: TURISMO | B12: SUMINISTRO_DE_ELECTRICIDAD_GAS_VAPOR_Y_AIRE_ACONDICIONADO
A13: MEDIO_AMBIENTE | B13: DISTRIBUCIÓN_DE_AGUA_EVACUACIÓN_Y_TRATAMIENTO_DE_AGUAS_RESIDUALES_GESTIÓN_DE_DESECHOS_Y_ACTIVIDADES_DE_SANEAMIENTO_AMBIENTAL
A14: COMERCIO_EC | B14: CONSTRUCCIÓN
B15: COMERCIO_AL_POR_MAYOR_Y_AL_POR_MENOR_REPARACIÓN_DE_VEHÍCULOS_AUTOMOTORES_Y_MOTOCICLETAS
B16: TRANSPORTE_Y_ALMACENAMIENTO
B17: ALOJAMIENTO_Y_SERVICIOS_DE_COMIDA
B18: INFORMACIÓN_Y_COMUNICACIONES
B19: ACTIVIDADES_FINANCIERAS_Y_DE_SEGUROS
B20: ACTIVIDADES_INMOBILIARIAS
B21: ACTIVIDADES_PROFESIONALES_CIENTÍFICAS_Y_TÉCNICAS
B22: ACTIVIDADES_DE_SERVICIOS_ADMINISTRATIVOS_Y_DE_APOYO
B23: ADMINISTRACIÓN_PÚBLICA_Y_DEFENSA_PLANES_DE_SEGURIDAD_SOCIAL_DE_AFILIACIÓN_OBLIGATORIA
B24: EDUCACIÓN
B25: ACTIVIDADES_DE_ATENCIÓN_DE_LA_SALUD_HUMANA_Y_DE_ASISTENCIA_SOCIAL
B26: ACTIVIDADES_ARTÍSTICAS_DE_ENTRETENIMIENTO_Y_RECREACIÓN
B27: OTRAS_ACTIVIDADES_DE_SERVICIOS

Sheet Sectores EC
A1: AGROPECUARIO | B1: AGROINDUSTRIA | C1: ARTESANÍAS | D1: TURISMO | E1: MEDIO_AMBIENTE | F1: |
A2: 0111 Cultivo de cereales (excepto arroz), legumbres y semillas oleaginosas | B2: 1011 Procesamiento y conservación de carne y productos cárnicos | C2: 1311 Preparación e hilatura de fibras textiles | D2: 5514 Alojamiento rural | E2: 3600 Captación, tratamiento y distribución de agua | F2: 4620 Comercio al por mayor de materias primas agropecuarias; animales vivos
A3: 0112 Cultivo de arroz | B3: 1012 Procesamiento y conservación de pescados, crustáceos y moluscos | C3: 1312 Tejeduría de productos textiles | D3: 5519 Otros tipos de alojamientos para visitantes | E3: 3700 Evacuación y tratamiento de aguas residuales | F3: 463 Comercio al por mayor de alimentos, bebidas y tabaco
A4: 0113 Cultivo de hortalizas, raíces y tubérculos | B4: 1020 Procesamiento y conservación de frutas, legumbres, hortalizas y tubérculos | C4: 1313 Acabado de productos textiles | D4: 5520 Actividades de zonas de camping y parques para vehículos recreacionales | E4: 3811 Recolección de desechos no peligrosos | F4: 4631 Comercio al por mayor de productos alimenticios
A5: 0114 Cultivo de tabaco | B5: 1030 Elaboración de aceites y grasas de origen vegetal y animal | C5: 1391 Fabricación de tejidos de punto y ganchillo | D5: 5590 Otros tipos de alojamiento n.c.p. | E5: 3812 Recolección de desechos peligrosos | F5: 4711 Comercio al por menor en establecimientos no especializados con surtido compuesto principalmente por alimentos, bebidas o tabaco
A6: 0115 Cultivo de plantas textiles | B6: 1040 Elaboración de productos lácteos | C6: 1392 Confección de artículos con materiales textiles, excepto prendas de vestir | D6: 5611 Expendio a la mesa de comidas preparadas | E6: 3821 Tratamiento y disposición de desechos no peligrosos | F6: 4721 Comercio al por menor de productos agrícolas para el consumo en establecimientos especializados
A7: 0119 Otros cultivos transitorios n.c.p. | B7: 1051 Elaboración de productos de molinería | C7: 1393 Fabricación de tapetes y alfombras para pisos | D7: 5612 Expendio por autoservicio de comidas preparadas | E7: 3830 Recuperación de materiales | F7: 4722 Comercio al por menor de leche, productos lácteos y huevos, en establecimientos especializados
A8: 0121 Cultivo de frutas tropicales y subtropicales | B8: 1052 Elaboración de almidones y productos derivados del almidón | C8: 1394 Fabricación de cuerdas, cordeles, cables, bramantes y redes | D8: 5619 Otros tipos de expendio de comidas preparadas n.c.p. | E8: 3900 Actividades de saneamiento ambiental y otros servicios de gestión de desechos | F8: 4723 Comercio al por menor de carnes (incluye aves de corral), productos cárnicos, pescados y productos de mar, en establecimientos especializados
A9: 0122 Cultivo de plátano y banano | B9: 1061 Trilla de café | C9: 1399 Fabricación de otros artículos textiles n.c.p. | D9: 5629 Actividades de otros servicios de comidas
A10: 0123 Cultivo de café | B10: 1062 Descafeinado, tostión y molienda del café | C10: 1410 Confección de prendas de vestir, excepto prendas de piel | D10: 7912 Actividades de operadores turísticos
A11: 0124 Cultivo de caña de azúcar | B11: 1063 Otros derivados del café | C11: 1420 Fabricación de artículos de piel | D11: 7990 Otros servicios de reserva y actividades relacionadas
A12: 0125 Cultivo de flor de corte | B12: 1071 Elaboración y refinación de azúcar | C12: 1430 Fabricación de artículos de punto y ganchillo
A13: 0126 Cultivo de palma para aceite (palma africana) y otros frutos oleaginosos | B13: 1072 Elaboración de panela | C13: 1511 Curtido y recurtido de cueros; recurtido y teñido de pieles
A14: 0127 Cultivo de plantas con las que se preparan bebidas | B14: 1081 Elaboración de productos de panadería | C14: 1512 Fabricación de artículos de viaje, bolsos de mano y artículos similares elaborados en cuero, y fabricación de artículos de talabartería y guarnicionería
A15: 0128 Cultivo de especias y de plantas aromáticas y medicinales | B15: 1082 Elaboración de cacao, chocolate y productos de confitería | C15: 1513 Fabricación de artículos de viaje, bolsos de mano y artículos similares; artículos de talabartería y guarnicionería elaborados en otros materiales
A16: 0129 Otros cultivos permanentes n.c.p. | B16: 1083 Elaboración de macarrones, fideos, alcuzcuz y productos farináceos similares | C16: 1521 Fabricación de calzado de cuero y piel, con cualquier tipo de suela
A17: 0130 Propagación de plantas (actividades de los viveros, excepto viveros forestales) | B17: 1084 Elaboración de comidas y platos preparados | C17: 1522 Fabricación de otros tipos de calzado, excepto calzado de cuero y piel
A18: 0141 Cría de ganado bovino y bufalino | B18: 1089 Elaboración de otros productos alimenticios n.c.p. | C18: 1523 Fabricación de partes del calzado
A19: 0142 Cría de caballos y otros equinos | B19: 1090 Elaboración de alimentos preparados para animales | C19: 1640 Fabricación de recipientes de madera
A20: 0143 Cría de ovejas y cabras | B20: 1102 Elaboración de bebidas fermentadas no destiladas | C20: 2023 Fabricación de jabones y detergentes, preparados para limpiar y pulir; perfumes y preparados de tocador
A21: 0144 Cría de ganado porcino | B21: 1103 Producción de malta, elaboración de cervezas y otras bebidas malteadas | C21: 2392 Fabricación de materiales de arcilla para la construcción
A22: 0145 Cría de aves de corral | B22: 1104 Elaboración de bebidas no alcohólicas, producción de aguas minerales y de otras aguas embotelladas | C22: 2393 Fabricación de otros productos de cerámica y porcelana
A23: 0149 Cría de otros animales n.c.p. | C23: 2396 Corte, tallado y acabado de la piedra
A24: 0150 Explotación mixta (agrícola y pecuaria) | C24: 3211 Fabricación de joyas y artículos conexos
A25: 0161 Actividades de apoyo a la agricultura | C25: 3212 Fabricación de bisutería y artículos conexos
A26: 0162 Actividades de apoyo a la ganadería
A27: 0163 Actividades posteriores a la cosecha
A28: 0164 Tratamiento de semillas para propagación
A29: 0170 Caza ordinaria y mediante trampas y actividades de servicios conexas
A30: 0210 Silvicultura y otras actividades forestales
A31: 0220 Extracción de madera
A32: 0230 Recolección de productos forestales diferentes a la madera
A33: 0240 Servicios de apoyo a la silvicultura
A34: 0311 Pesca marítima
A35: 0312 Pesca de agua dulce
A36: 0321 Acuicultura marítima
A37: 0322 Acuicultura de agua dulce

Sheet Sectores EP
A1: AGRICULTURA_GANADERÍA_CAZA_SILVICULTURA_Y_PESCA | B1: EXPLOTACIÓN_DE_MINAS_Y_CANTERAS | C1: INDUSTRIAS_MANUFACTURERAS | D1: SUMINISTRO_DE_ELECTRICIDAD_GAS_VAPOR_Y_AIRE_ACONDICIONADO | E1: DISTRIBUCIÓN_DE_AGUA_EVACUACIÓN_Y_TRATAMIENTO_DE_AGUAS_RESIDUALES_GESTIÓN_DE_DESECHOS_Y_ACTIVIDADES_DE_SANEAMIENTO_AMBIENTAL | F1: CONSTRUCCIÓN | G1: COMERCIO_AL_POR_MAYOR_Y_AL_POR_MENOR_REPARACIÓN_DE_VEHÍCULOS_AUTOMOTORES_Y_MOTOCICLETAS | H1: TRANSPORTE_Y_ALMACENAMIENTO | I1: ALOJAMIENTO_Y_SERVICIOS_DE_COMIDA | J1: INFORMACIÓN_Y_COMUNICACIONES | K1: ACTIVIDADES_FINANCIERAS_Y_DE_SEGUROS | L1: ACTIVIDADES_INMOBILIARIAS | M1: ACTIVIDADES_PROFESIONALES_CIENTÍFICAS_Y_TÉCNICAS | N1: ACTIVIDADES_DE_SERVICIOS_ADMINISTRATIVOS_Y_DE_APOYO | O1: ADMINISTRACIÓN_PÚBLICA_Y_DEFENSA_PLANES_DE_SEGURIDAD_SOCIAL_DE_AFILIACIÓN_OBLIGATORIA | P1: EDUCACIÓN | Q1: ACTIVIDADES_DE_ATENCIÓN_DE_LA_SALUD_HUMANA_Y_DE_ASISTENCIA_SOCIAL | R1: ACTIVIDADES_ARTÍSTICAS_DE_ENTRETENIMIENTO_Y_RECREACIÓN | S1: OTRAS_ACTIVIDADES_DE_SERVICIOS
A2: 0111 Cultivo de cereales (excepto arroz), legumbres y semillas oleaginosas | B2: 0510 Extracción de hulla (carbón de piedra) | C2: 1011 Procesamiento y conservación de carne y productos cárnicos | D2: 3511 Generación de energía eléctrica | E2: 3600 Captación, tratamiento y distribución de agua | F2: 4111 Construcción de edificios residenciales | G2: 4511 Comercio de vehículos automotores nuevos | H2: 4911 Transporte férreo de pasajeros | I2: 5511 Alojamiento en hoteles | J2: 5811 Edición de libros | K2: 6411 Banco Central | L2: 6810 Actividades inmobiliarias realizadas con bienes propios o arrendados | M2: 6910 Actividades jurídicas | N2: 7710 Alquiler y arrendamiento de vehículos automotores | O2: 8411 Actividades legislativas de la administración pública | P2: 8511 Educación de la primera infancia | Q2: 8610 Actividades de hospitales y clínicas, con internación | R2: 9001 Creación literaria | S2: 9411 Actividades de asociaciones empresariales y de empleadores
A3: 0112 Cultivo de arroz | B3: 0520 Extracción de carbón lignito | C3: 1012 Procesamiento y conservación de pescados, crustáceos y moluscos | D3: 3512 Transmisión de energía eléctrica | E3: 3700 Evacuación y tratamiento de aguas residuales | F3: 4112 Construcción de edificios no residenciales | G3: 4512 Comercio de vehículos automotores usados | H3: 4912 Transporte férreo de carga | I3: 5512 Alojamiento en apartahoteles | J3: 5812 Edición de directorios y listas de correo | K3: 6412 Bancos comerciales | L3: 6820 Actividades inmobiliarias realizadas a cambio de una retribución o por contrata | M3: 6920 Actividades de contabilidad, teneduría de libros, auditoría financiera y asesoría tributaria | N3: 7721 Alquiler y arrendamiento de equipo recreativo y deportivo | O3: 8412 Actividades ejecutivas de la administración pública | P3: 8512 Educación preescolar | Q3: 8621 Actividades de la práctica médica, sin internación | R3: 9002 Creación musical | S3: 9412 Actividades de asociaciones profesionales
A4: 0113 Cultivo de hortalizas, raíces y tubérculos | B4: 0610 Extracción de petróleo crudo | C4: 1020 Procesamiento y conservación de frutas, legumbres, hortalizas y tubérculos | D4: 3513 Distribución de energía eléctrica | E4: 3811 Recolección de desechos no peligrosos | F4: 4210 Construcción de carreteras y vías de ferrocarril | G4: 4520 Mantenimiento y reparación de vehículos automotores | H4: 4921 Transporte de pasajeros | I4: 5513 Alojamiento en centros vacacionales | J4: 5813 Edición de periódicos, revistas y otras publicaciones periódicas | K4: 6421 Actividades de las corporaciones financieras | M4: 7010 Actividades de administración empresarial | N4: 7722 Alquiler de videos y discos | O4: 8413 Regulación de las actividades de organismos que prestan servicios de salud, educativos, culturales y otros servicios sociales, excepto servicios de seguridad social | P4: 8513 Educación básica primaria | Q4: 8622 Actividades de la práctica odontológica | R4: 9003 Creación teatral | S4: 9420 Actividades de sindicatos de empleados
A5: 0114 Cultivo de tabaco | B5: 0620 Extracción de gas natural | C5: 1030 Elaboración de aceites y grasas de origen vegetal y animal | D5: 3514 Comercialización de energía eléctrica | E5: 3812 Recolección de desechos peligrosos | F5: 4220 Construcción de proyectos de servicio público | G5: 4530 Comercio de partes, piezas (autopartes) y accesorios (lujos) para vehículos automotores | H5: 4922 Transporte mixto | I5: 5514 Alojamiento rural | J5: 5819 Otros trabajos de edición | K5: 6422 Actividades de las compañías de financiamiento | M5: 7020 Actividades de consultaría de gestión | N5: 7729 Alquiler y arrendamiento de otros efectos personales y enseres domésticos n.c.p. | O5: 8414 Actividades reguladoras y facilitadoras de la actividad económica | P5: 8521 Educación básica secundaria | Q5: 8691 Actividades de apoyo diagnóstico | R5: 9004 Creación audiovisual | S5: 9491 Actividades de asociaciones religiosas
A6: 0115 Cultivo de plantas textiles | B6: 0710 Extracción de minerales de hierro | C6: 1040 Elaboración de productos lácteos | D6: 3520 Producción de gas; distribución de combustibles gaseosos por tuberías | E6: 3821 Tratamiento y disposición de desechos no peligrosos | F6: 4290 Construcción de otras obras de ingeniería civil | G6: 4541 Comercio de motocicletas y de sus partes, piezas y accesorios | H6: 4923 Transporte de carga por carretera | I6: 5519 Otros tipos de alojamientos para visitantes | J6: 5820 Edición de programas de informática (software) | K6: 6423 Banca de segundo piso | M6: 7110 Actividades de arquitectura e ingeniería y otras actividades conexas de consultoría técnica | N6: 7730 Alquiler y arrendamiento de otros tipos de maquinaria, equipo y bienes tangibles n.c.p. | O6: 8415 Actividades de los otros órganos de control | P6: 8522 Educación media académica | Q6: 8692 Actividades de apoyo terapéutico | R6: 9005 Artes plásticas y visuales | S6: 9492 Actividades de asociaciones políticas
A7: 0119 Otros cultivos transitorios n.c.p. | B7: 0721 Extracción de minerales de uranio y de torio | C7: 1051 Elaboración de productos de molinería | D7: 3530 Suministro de vapor y aire acondicionado | E7: 3822 Tratamiento y disposición de desechos peligrosos | F7: 4311 Demolición | G7: 4542 Mantenimiento y reparación de motocicletas y de sus partes y piezas | H7: 4930 Transporte por tuberías | I7: 5520 Actividades de zonas de camping y parques para vehículos recreacionales | J7: 5911 Actividades de producción de películas cinematográficas, videos, programas, anuncios y comerciales de televisión | K7: 6424 Actividades de las cooperativas financieras | M7: 7120 Ensayos y análisis técnicos | N7: 7740 Arrendamiento de propiedad intelectual y productos similares, excepto obras protegidas por derechos de autor | O7: 8421 Relaciones exteriores | P7: 8523 Educación media técnica y de formación laboral | Q7: 8699 Otras actividades de atención de la salud humana | R7: 9006 Actividades teatrales | S7: 9499 Actividades de otras asociaciones n.c.p.
A8: 0121 Cultivo de frutas tropicales y subtropicales | B8: 0722 Extracción de oro y otros metales preciosos | C8: 1052 Elaboración de almidones y productos derivados del almidón | E8: 3830 Recuperación de materiales | F8: 4312 Preparación del terreno | G8: 4620 Comercio al por mayor de materias primas agropecuarias; animales vivos | H8: 5011 Transporte de pasajeros marítimo y de cabotaje | I8: 5530 Servicio por horas | J8: 5912 Actividades de posproducción de películas cinematográficas, videos, programas, anuncios y comerciales de televisión | K8: 6431 Fideicomisos, fondos y entidades financieras similares | M8: 7210 Investigaciones y desarrollo experimental en el campo de las ciencias naturales y la ingeniería | N8: 7810 Actividades de agencias de empleo | O8: 8422 Actividades de defensa | P8: 8530 Establecimientos que combinan diferentes niveles de educación | Q8: 8710 Actividades de atención residencial medicalizada de tipo general | R8: 9007 Actividades de espectáculos musicales en vivo | S8: 9511 Mantenimiento y reparación de computadores y de equipo periférico
A9: 0122 Cultivo de plátano y banano | B9: 0723 Extracción de minerales de níquel | C9: 1061 Trilla de café | E9: 3900 Actividades de saneamiento ambiental y otros servicios de gestión de desechos | F9: 4321 Instalaciones eléctricas | G9: 4631 Comercio al por mayor de productos alimenticios | H9: 5012 Transporte de carga marítimo y de cabotaje | I9: 5590 Otros tipos de alojamiento n.c.p. | J9: 5913 Actividades de distribución de películas cinematográficas, videos, programas, anuncios y comerciales de televisión | K9: 6432 Fondos de cesantías | M9: 7220 Investigaciones y desarrollo experimental en el campo de las ciencias sociales y las humanidades | N9: 7820 Actividades de agencias de empleo temporal | O9: 8423 Orden público y actividades de seguridad | P9: 8541 Educación técnica profesional | Q9: 8720 Actividades de atención residencial, para el cuidado de pacientes con retardo mental, enfermedad mental y consumo de sustancias psicoactivas | R9: 9008 Otras actividades de espectáculos en vivo | S9: 9512 Mantenimiento y reparación de equipos de comunicación
A10: 0123 Cultivo de café | B10: 0724 Extracción de otros minerales metalíferos no ferrosos n.c.p. | C10: 1062 Descafeinado, tostión y molienda del café | F10: 4322 Instalaciones de fontanería, calefacción y aire acondicionado | G10: 4632 Comercio al por mayor de bebidas y tabaco | H10: 5021 Transporte fluvial de pasajeros | I10: 5611 Expendio a la mesa de comidas preparadas | J10: 5914 Actividades de exhibición de películas cinematográficas y videos | K10: 6491 Leasing financiero (arrendamiento financiero) | M10: 7310 Publicidad | N10: 7830 Otras actividades de suministro de recurso humano | O10: 8424 Administración de justicia | P10: 8542 Educación tecnológica | Q10: 8730 Actividades de atención en instituciones para el cuidado de personas mayores y/o discapacitadas | R10: 9101 Actividades de bibliotecas y archivos | S10: 9521 Mantenimiento y reparación de aparatos electrónicos de consumo
A11: 0124 Cultivo de caña de azúcar | B11: 0811 Extracción de piedra, arena, arcillas comunes, yeso y anhidrita | C11: 1063 Otros derivados del café | F11: 4329 Otras instalaciones especializadas | G11: 4641 Comercio al por mayor de productos textiles, productos confeccionados para uso doméstico | H11: 5022 Transporte fluvial de carga | I11: 5612 Expendio por autoservicio de comidas preparadas | J11: 5920 Actividades de grabación de sonido y edición de música | K11: 6492 Actividades financieras de fondos de empleados y otras formas asociativas del sector solidario | M11: 7320 Estudios de mercado y realización de encuestas de opinión pública | N11: 7911 Actividades de las agencias de viaje | O11: 8430 Actividades de planes de seguridad social de afiliación obligatoria | P11: 8543 Educación de instituciones universitarias o de escuelas tecnológicas | Q11: 8790 Otras actividades de atención en instituciones con alojamiento | R11: 9102 Actividades y funcionamiento de museos, conservación de edificios y sitios históricos | S11: 9522 Mantenimiento y reparación de aparatos y equipos domésticos y de jardinería
A12: 0125 Cultivo de flor de corte | B12: 0812 Extracción de arcillas de uso industrial, caliza, caolín y bentonitas | C12: 1071 Elaboración y refinación de azúcar | F12: 4330 Terminación y acabado de edificios y obras de ingeniería civil | G12: 4642 Comercio al por mayor de prendas de vestir | H12: 5111 Transporte aéreo nacional de pasajeros | I12: 5613 Expendio de comidas preparadas en cafeterías | J12: 6010 Actividades de programación y transmisión en el servicio de radiodifusión sonora | K12: 6493 Actividades de compra de cartera o factoring | M12: 7410 Actividades especializadas de diseño | N12: 7912 Actividades de operadores turísticos | P12: 8544 Educación de universidades | Q12: 8810 Actividades de asistencia social sin alojamiento para personas mayores y discapacitadas | R12: 9103 Actividades de jardines botánicos, zoológicos y reservas naturales | S12: 9523 Reparación de calzado y artículos de cuero
A13: 0126 Cultivo de palma para aceite (palma africana) y otros frutos oleaginosos | B13: 0820 Extracción de esmeraldas, piedras preciosas y semipreciosas | C13: 1072 Elaboración de panela | F13: 4390 Otras actividades especializadas para la construcción de edificios y obras de ingeniería civil | G13: 4643 Comercio al por mayor de calzado | H13: 5112 Transporte aéreo internacional de pasajeros | I13: 5619 Otros tipos de expendio de comidas preparadas n.c.p. | J13: 6020 Actividades de programación y transmisión de televisión | K13: 6494 Otras actividades de distribución de fondos | M13: 7420 Actividades de fotografía | N13: 7990 Otros servicios de reserva y actividades relacionadas | P13: 8551 Formación académica no formal | Q13: 8890 Otras actividades de asistencia social sin alojamiento | R13: 9200 Actividades de juegos de azar y apuestas | S13: 9524 Reparación de muebles y accesorios para el hogar
A14: 0127 Cultivo de plantas con las que se preparan bebidas | B14: 0891 Extracción de minerales para la fabricación de abonos y productos químicos | C14: 1081 Elaboración de productos de panadería | G14: 4644 Comercio al por mayor de aparatos y equipo de uso doméstico | H14: 5121 Transporte aéreo nacional de carga | I14: 5621 Catering para eventos | J14: 6110 Actividades de telecomunicaciones alámbricas | K14: 6495 Instituciones especiales oficiales | M14: 7490 Otras actividades profesionales, científicas y técnicas n.c.p. | N14: 8010 Actividades de seguridad privada | P14: 8552 Enseñanza deportiva y recreativa | R14: 9311 Gestión de instalaciones deportivas | S14: 9529 Mantenimiento y reparación de otros efectos personales y enseres domésticos
A15: 0128 Cultivo de especias y de plantas aromáticas y medicinales | B15: 0892 Extracción de halita (sal) | C15: 1082 Elaboración de cacao, chocolate y productos de confitería | G15: 4645 Comercio al por mayor de productos farmacéuticos, medicinales, cosméticos y de tocador | H15: 5122 Transporte aéreo internacional de carga | I15: 5629 Actividades de otros servicios de comidas | J15: 6120 Actividades de telecomunicaciones inalámbricas | K15: 6499 Otras actividades de servicio financiero, excepto las de seguros y pensiones n.c.p. | M15: 7500 Actividades veterinarias | N15: 8020 Actividades de servicios de sistemas de seguridad | P15: 8553 Enseñanza cultural | R15: 9312 Actividades de clubes deportivos | S15: 9601 Lavado y limpieza, incluso la limpieza en seco, de productos textiles y de piel
A16: 0129 Otros cultivos permanentes n.c.p. | B16: 0899 Extracción de otros minerales no metálicos n.c.p. | C16: 1083 Elaboración de macarrones, fideos, alcuzcuz y productos farináceos similares | G16: 4649 Comercio al por mayor de otros utensilios domésticos n.c.p. | H16: 5210 Almacenamiento y depósito | I16: 5630 Expendio de bebidas alcohólicas para el consumo dentro del establecimiento | J16: 6130 Actividades de telecomunicación satelital | K16: 6511 Seguros generales | N16: 8030 Actividades de detectives e investigadores privados | P16: 8559 Otros tipos de educación n.c.p. | R16: 9319 Otras actividades deportivas | S16: 9602 Peluquería y otros tratamientos de belleza
A17: 0130 Propagación de plantas (actividades de los viveros, excepto viveros forestales) | B17: 0910 Actividades de apoyo para la extracción de petróleo y de gas natural | C17: 1084 Elaboración de comidas y platos preparados | G17: 4651 Comercio al por mayor de computadores, equipo periférico y programas de informática | H17: 5221 Actividades de estaciones, vías y servicios complementarios para el transporte terrestre | J17: 6190 Otras actividades de telecomunicaciones | K17: 6512 Seguros de vida | N17: 8110 Actividades combinadas de apoyo a instalaciones | P17: 8560 Actividades de apoyo a la educación | R17: 9321 Actividades de parques de atracciones y parques temáticos | S17: 9603 Pompas fúnebres y actividades relacionadas
A18: 0141 Cría de ganado bovino y bufalino | B18: 0990 Actividades de apoyo para otras actividades de explotación de minas y canteras | C18: 1089 Elaboración de otros productos alimenticios n.c.p. | G18: 4652 Comercio al por mayor de equipo, partes y piezas electrónicos y de telecomunicaciones | H18: 5222 Actividades de puertos y servicios complementarios para el transporte acuático | J18: 6201 Actividades de desarrollo de sistemas informáticos (planificación, análisis, diseño, programación, pruebas) | K18: 6513 Reaseguros | N18: 8121 Limpieza general interior de edificios | R18: 9329 Otras actividades recreativas y de esparcimiento n.c.p. | S18: 9609 Otras actividades de servicios personales n.c.p.
A19: 0142 Cría de caballos y otros equinos | C19: 1090 Elaboración de alimentos preparados para animales | G19: 4653 Comercio al por mayor de maquinaria y equipo agropecuarios | H19: 5223 Actividades de aeropuertos, servicios de navegación aérea y demás actividades conexas al transporte aéreo | J19: 6202 Actividades de consultoría informática y actividades de administración de instalaciones informáticas | K19: 6514 Capitalización | N19: 8129 Otras actividades de limpieza de edificios e instalaciones industriales
A20: 0143 Cría de ovejas y cabras | C20: 1102 Elaboración de bebidas fermentadas no destiladas | G20: 4659 Comercio al por mayor de otros tipos de maquinaria y equipo n.c.p. | H20: 5224 Manipulación de carga | J20: 6209 Otras actividades de tecnologías de información y actividades de servicios informáticos | K20: 6521 Servicios de seguros sociales de salud | N20: 8130 Actividades de paisajismo y servicios de mantenimiento conexos
A21: 0144 Cría de ganado porcino | C21: 1103 Producción de malta, elaboración de cervezas y otras bebidas malteadas | G21: 4661 Comercio al por mayor de combustibles sólidos, líquidos, gaseosos y productos conexos | H21: 5229 Otras actividades complementarias al transporte | J21: 6311 Procesamiento de datos, alojamiento (hosting) y actividades relacionadas | K21: 6522 Servicios de seguros sociales de riesgos profesionales | N21: 8211 Actividades combinadas de servicios administrativos de oficina
A22: 0145 Cría de aves de corral | C22: 1104 Elaboración de bebidas no alcohólicas, producción de aguas minerales y de otras aguas embotelladas | G22: 4662 Comercio al por mayor de metales y productos metalíferos | H22: 5310 Actividades postales nacionales | J22: 6312 Portales web | K22: 6531 Régimen de prima media con prestación definida (RPM) | N22: 8219 Fotocopiado, preparación de documentos y otras actividades especializadas de apoyo a oficina
A23: 0149 Cría de otros animales n.c.p. | C23: 1200 Elaboración de productos de tabaco | G23: 4663 Comercio al por mayor de materiales de construcción, artículos de ferretería, pinturas, productos de vidrio, equipo y materiales de fontanería y calefacción | H23: 5320 Actividades de mensajería | J23: 6391 Actividades de agencias de noticias | K23: 6532 Régimen de ahorro individual (RAI) | N23: 8220 Actividades de centros de llamadas (Call center)
A24: 0150 Explotación mixta (agrícola y pecuaria) | C24: 1311 Preparación e hilatura de fibras textiles | G24: 4664 Comercio al por mayor de productos químicos básicos, cauchos y plásticos en formas primarias y productos químicos de uso agropecuario | J24: 6399 Otras actividades de servicio de información n.c.p. | K24: 6611 Administración de mercados financieros | N24: 8230 Organización de convenciones y eventos comerciales
A25: 0161 Actividades de apoyo a la agricultura | C25: 1312 Tejeduría de productos textiles | G25: 4665 Comercio al por mayor de desperdicios, desechos y chatarra | K25: 6612 Corretaje de valores y de contratos de productos básicos | N25: 8291 Actividades de agencias de cobranza y oficinas de calificación crediticia
A26: 0162 Actividades de apoyo a la ganadería | C26: 1313 Acabado de productos textiles | G26: 4669 Comercio al por mayor de otros productos n.c.p. | K26: 6613 Otras actividades relacionadas con el mercado de valores | N26: 8292 Actividades de envase y empaque
A27: 0163 Actividades posteriores a la cosecha | C27: 1391 Fabricación de tejidos de punto y ganchillo | G27: 4690 Comercio al por mayor no especializado | K27: 6614 Actividades de las casas de cambio | N27: 8299 Otras actividades de servicio de apoyo a las empresas n.c.p.
A28: 0164 Tratamiento de semillas para propagación | C28: 1392 Confección de artículos con materiales textiles, excepto prendas de vestir | G28: 4711 Comercio al por menor en establecimientos no especializados con surtido compuesto principalmente por alimentos, bebidas o tabaco | K28: 6615 Actividades de los profesionales de compra y venta de divisas
A29: 0170 Caza ordinaria y mediante trampas y actividades de servicios conexas | C29: 1393 Fabricación de tapetes y alfombras para pisos | G29: 4719 Comercio al por menor en establecimientos no especializados, con surtido compuesto principalmente por productos diferentes de alimentos (víveres en general), bebidas y tabaco | K29: 6619 Otras actividades auxiliares de las actividades de servicios financieros n.c.p.
A30: 0210 Silvicultura y otras actividades forestales | C30: 1394 Fabricación de cuerdas, cordeles, cables, bramantes y redes | G30: 4721 Comercio al por menor de productos agrícolas para el consumo en establecimientos especializados | K30: 6621 Actividades de agentes y corredores de seguros
A31: 0220 Extracción de madera | C31: 1399 Fabricación de otros artículos textiles n.c.p. | G31: 4722 Comercio al por menor de leche, productos lácteos y huevos, en establecimientos especializados | K31: 6629 Evaluación de riesgos y daños, y otras actividades de servicios auxiliares
A32: 0230 Recolección de productos forestales diferentes a la madera | C32: 1410 Confección de prendas de vestir, excepto prendas de piel | G32: 4723 Comercio al por menor de carnes (incluye aves de corral), productos cárnicos, pescados y productos de mar, en establecimientos especializados | K32: 6630 Actividades de administración de fondos
A33: 0240 Servicios de apoyo a la silvicultura | C33: 1420 Fabricación de artículos de piel | G33: 4724 Comercio al por menor de bebidas y productos del tabaco, en establecimientos especializados
A34: 0311 Pesca marítima | C34: 1430 Fabricación de artículos de punto y ganchillo | G34: 4729 Comercio al por menor de otros productos alimenticios n.c.p., en establecimientos especializados
A35: 0312 Pesca de agua dulce | C35: 1511 Curtido y recurtido de cueros; recurtido y teñido de pieles | G35: 4731 Comercio al por menor de combustible, lubricantes, aditivos y productos de limpieza para automotores, en establecimientos especializados
A36: 0321 Acuicultura marítima | C36: 1512 Fabricación de artículos de viaje, bolsos de mano y artículos similares elaborados en cuero, y fabricación de artículos de talabartería y guarnicionería | G36: 4732 Comercio al por menor de combustible para automotores
A37: 0322 Acuicultura de agua dulce | C37: 1513 Fabricación de artículos de viaje, bolsos de mano y artículos similares; artículos de talabartería y guarnicionería elaborados en otros materiales | G37: 4741 Comercio al por menor de lubricantes (aceites, grasas), aditivos y productos de limpieza para vehículos automotores
C38: 1521 Fabricación de calzado de cuero y piel, con cualquier tipo de suela | G38: 4742 Comercio al por menor de equipos y aparatos de sonido y de video, en establecimientos especializados
C39: 1522 Fabricación de otros tipos de calzado, excepto calzado de cuero y piel | G39: 4751 Comercio al por menor de productos textiles en establecimientos especializados
C40: 1523 Fabricación de partes del calzado | G40: 4752 Comercio al por menor de artículos de ferretería, pinturas y productos de vidrio en establecimientos especializados
...

Sheet PROYECTO
B6: Coordinación Nacional de Emprendimiento, Dirección de Empleo y Trabajo (2025)
B7: PROYECTO ESPECIAL (LÍNEA CREAR) | BM7: SI | BN7: CC | BO7: Aporte Emprendedor
BM8: NO | BN8: CE | BO8: Fondo Emprender
B9: NOMBRES Y APELLIDOS DEL LÍDER DEL PROYECTO | T9: TIPO DE DOCUMENTO | AC9: NÚMERO
BM11: Femenino | BQ11: Adolescentes en Conflicto con la Ley Penal
BM12: Masculino | BQ12: Adolescente Trabajador
B13: NOMBRE DEL PROYECTO | T13: DEPARTAMENTO | AC13: MUNICIPIO | BM13: Otro | BQ13: Adolescentes y Jóvenes Vulnerables
BQ14: Afrocolombianos
BM15: Gestión y Administración | BQ15: Campesino
BM16: Transparencia y Responsabilidad: | BQ16: Desplazado por fenómenos naturales
B17: TIPO PROYECTO | L17: SECTOR | Z17: ACTIVIDAD ECONÓMICA
B21: ¿Es un proyecto asociativo? | U21: ¿Cuántas personas hacen parte del equipo asociativo? | AV21: SI | BQ21: Palenqueros
AV22: NO | BM22: Contrato Laboral a término fijo | BQ22: Participanes del programa de reintegración - Reintegrados (ARN)
B23: ¿Cuenta con un lugar de operaciones? | BM23: Contrato Laboral a término indefinido | BQ23: Personas en Proceso de Reincorporación
BM24: Prestación de servicios | BQ24: Población LGBTI
A25: Para desarrollar su proyecto debe contar con un lugar de operaciones. Si llega a ser beneficiario de los recursos del Fondo Emprender, en el momento de la suscripción del contrato de cooperación empresarial, se debe evidenciar la gestión del sitio de operaciones; para este caso, se solicita que, se presente uso de suelos donde se tiene planeado realizar la actividad económica y el certificado de tradición donde se demuestre la sana posesión del inmueble o certificación de la sana posesión(Alcaldía). Si el predio está en sucesión se recomienda haber iniciado el proceso o iniciarlo y que se cuente con la autorización de todos los involucrados. El plazo máximo será no mayor a un mes de la suscripción del acta de inicio del contrato de cooperación empresarial para estos documentos. En caso de superar este plazo, el contrato de cooperación empresarial se terminará unilateralmente, por lo que es fundamental prever el lugar de operaciones de su proyecto desde este momento, la formulación de su proyecto. | BM25: Contrato por obra o Labor | BQ25: Población con discapacidad
A26: Al tomar la decisión de desarrollar un proyecto es importante tener clara la información de ¿Qué queremos hacer? ¿Cómo lo vamos a hacer? ¿Que vamos a vender? ¿Quien nos va a comprar? entre otros. Con el acompañamiento del SENA, vamos a orientarlo para que construya su iniciativa productiva. | BM26: Jornal | BQ26: Población indígena
BQ27: Población víctima de minas antipersona
BM28: 1 | BQ28: Pueblo ROM
BM29: 2 | BQ29: Raizales
BM30: 3 | BQ30: Remitidos por programa de adaptación laboral - PAL
BM31: 4 | BQ31: Soldados campesinos
BM32: 5 | BQ32: Tercera edad
BM33: 6 | BQ33: Veteranos
BM34: 7 | BQ34: Víctima de otros hechos victimizantes
BM35: 8 | BQ35: Víctima de violencia
BM36: 9 | BQ36: Víctimas Sobrevivientes con Agentes Químicos
BM37: 10
BM38: 11
BM39: 12
A47: INSTRUCCIONES GENERALES:
A48: Para el diligenciamiento de esta herramienta, se debe tener el acompañamiento del Centro de Desarrollo Empresarial del SENA más cercano, donde el equipo de profesionales realizará al menos cinco (5) entrenamientos para guiarlo en la construcción del proyecto y el diligenciamiento de esta herramienta. Diligenciar solamente las celdas sombreadas en gris. Se solicita mantener la estructura original de la herramienta, sin realizar cambios en las columnas, pestañas, fórmulas, formatos de celdas o cualquier otro elemento que afecte su integridad. Solo se considerará la información que se pueda visualizar en cada celda, POR FAVOR, no agregar información que no se pueda visualizar, dado que no será tenida en cuenta en el proceso de evaluación.
A52: 1.¿QUIEN ES EL CLIENTE DE SU PROYECTO? (Quien compra mis productos o servicios)
A54: En este espacio debe identificar "El cliente" ese que le va a comprar sus productos o servicios, lo más detallado posible, como se conoce a un hijo o a un familiar muy cercano.
A57: CARACTERÍSTICAS DEL CLIENTE O CONSUMIDOR (Por favor indicar frente al cliente, ubicación geográfica, estrato, edad, género, capacidad de compra, si trabaja, si tiene hijos, si vive en casa propia o arriendo) Incluya cifras y estadísticas | S57: CUALIDADES DEL CLIENTE O CONSUMIDOR (Por favor indicar gustos, preferencias, que le da miedo, que le hace feliz, cuales son sus valores, que le gusta comer, si le gusta viajar, entre otros)
A60: CLIENTE
A66: CONSUMIDOR
A73: 2. PLANTEAMIENTO DEL PROBLEMA O NECESIDAD QUE SE PRETENDE SOLUCIONAR
A74: En este espacio se responde a la pregunta ¿Cuál es el problema o necesidad que se pretende solucionar? ¿Cómo le estoy ayudando al cliente) Ojo! No es su problema personal o del grupo asociativo, sino el problema o necesidad del posible cliente del punto anterior.
A89: 3. LA COMPETENCIA (Quien más lo hace?)
...

Sheet GRUPO ASOCIATIVO
B4: INFORMACIÓN DE LOS INTEGRANTES DEL PROYECTO ASOCIATIVO DE ECONOMÍA CAMPESINA
B7: Si su proyecto es asociativo, por favor diligencie toda la información de las personas que hacen parte del equipo asociativo
B9: Frente al elemento "Función principal" de cada uno de los miembros del equipo asociativo, deben clasificarse así:
B10: 1. Gestión y Administración: - Establecer y mantener una estructura de gobierno eficaz. - Designar y supervisar a los miembros de la junta directiva u órganos de gobierno. - Garantizar el cumplimiento de los estatutos, reglamentos internos y normativas legales aplicables. 2. Transparencia y Responsabilidad: - Mantener registros precisos y transparentes de las actividades y decisiones de la asociación. - Presentar informes financieros y de actividades de manera periódica a los miembros y otras partes interesadas. - Actuar de manera 3. Gestión de Recursos: - Administrar eficientemente los recursos financieros y materiales de la asociación. - Garantizar que los fondos se utilicen de manera adecuada y en línea con los objetivos de la asociación. - Buscar fuentes de financiamiento sostenibles para apoyar las actividades de la asociación ética y responsable en todas las actividades de la asociación. 4. Relaciones con los Miembros y la Comunidad: - Fomentar la participación activa y el compromiso de los miembros en las actividades de la asociación. - Mantener una comunicación abierta y efectiva con los miembros, socios y otras partes interesadas. - Colaborar con otras organizaciones y entidades para promover los objetivos de la asociación. 5. Cumplimiento Legal: - Cumplir con todas las leyes y regulaciones aplicables a la asociación. - Presentar informes fiscales y legales requeridos por las autoridades competentes. - Proteger los derechos y el bienestar de los miembros, empleados y otras partes interesadas.
B14: INFORMACIÓN DE LOS INTEGRANTES DEL PROYECTO ASOCIATIVO DE ECONOMÍA CAMPESINA
B15: Nombres y Apellidos Completos | C15: Tipo de Documento de identidad | D15: Número de documento | E15: Rol dentro del grupo | F15: Participación % en la toma de decisiones | G15: Función principal | H15: Género | I15: Edad | K15: Caracterización | N15: Teléfono Contacto | O15: Ingresos Mensuales Promedio
Q16: Tipo de documento | S16: Función Principal | U16: Genero | W16: Caracterización
Q17: CC | S17: Gestión y Administración | U17: Femenino | W17: Adolescentes en Conflicto con la Ley Penal
Q18: CE | S18: Transparencia y Responsabilidad: | U18: Masculino | W18: Adolescente Trabajador
S19: Gestión de Recursos | U19: Otro | W19: Adolescentes y Jóvenes Vulnerables
S20: Relaciones con los Miembros y la Comunidad | W20: Afrocolombianos
S21: Cumplimiento Legal | W21: Campesino
W22: Desplazado por fenómenos naturales
W23: Migrantes que retornan al país
W24: Mujer cabeza de hogar
W25: Negritudes
W26: Ninguno
W27: Palenqueros
W28: Participanes del programa de reintegración - Reintegrados (ARN)
W29: Personas en Proceso de Reincorporación
W30: Población LGBTI
W31: Población con discapacidad
W32: Población indígena
W33: Población víctima de minas antipersona
... W41: Víctima de violencia

Sheet MODELO FINANCIERO
B5: VALOR DEL PROYECTO | C5: =+PROYECTO!AE448 -> 0
B6: VALOR DEL APORTE | C6: =+PROYECTO!AE449 -> 0 | D6: =+IF((C6>=(C5*0.1)),"CUMPLE","NO CUMPLE") -> CUMPLE | E6: Aporte Emprendedor
B7: VALOR SOLICITADO AL FONDO | C7: =+PROYECTO!AE450 -> 0
B8: Diligenciar la tasa de descuento
B10: Respetado Emprendedor: El monto debe coincidir con la información consignada en la celda R20 de la hoja Proyecto frente a la pregunta ¿Es un proyecto asociativo? | D10: =+IF(AND(PROYECTO!R21="NO",PROYECTO!AE450<=PROYECTO!AE451,PROYECTO!AE450>0),("MONTO SOLICITADO CORRESPONDE LINEA CREAR IND"),("MONTO SOLICITADO NO CORRESPONDE LINEA CREAR IND")) -> MONTO SOLICITADO NO CORRESPONDE LINEA CREAR IND
D11: =+IF(AND(PROYECTO!R21="SI",PROYECTO!AE450<=PROYECTO!AS453),("MONTO SOLICITADO CORRESPONDE LINEA CREAR ASOC"),("MONTO SOLICITADO NO CORRESPONDE LINEA CREAR ASOC")) -> MONTO SOLICITADO NO CORRESPONDE LINEA CREAR ASOC
B12: =+PROYECTO!R21 -> 0
B13: ESTADO DE RESULTADOS | D13: AÑO 1 | E13: AÑO 2 | F13: AÑO 3
B14: Ventas | D14: =+PROYECTO!K253+PROYECTO!K271+PROYECTO!K289 -> 0 | E14: =+PROYECTO!W253+PROYECTO!W271+PROYECTO!W289 -> 0 | F14: =+PROYECTO!AI253+PROYECTO!AI271+PROYECTO!AI289 -> 0
B15: Materia Prima | D15: =+(PROYECTO!G253*PROYECTO!AE323)+(PROYECTO!AE332*PROYECTO!G271)+(PROYECTO!G289*PROYECTO!AE341) -> 0 | E15: =((PROYECTO!S253)*(PROYECTO!AE323*(1+PROYECTO!F224)))+(PROYECTO!S271*(PROYECTO!AE332*(1+PROYECTO!F224)))+(PROYECTO!S289*(PROYECTO!AE341*(1+PROYECTO!F224))) -> 0 | F15: =+(PROYECTO!AE253*(PROYECTO!AE323*(1+PROYECTO!F224+PROYECTO!I224)))+(PROYECTO!AE271*(PROYECTO!AE332*(1+PROYECTO!F224+PROYECTO!I224)))+(PROYECTO!AE289*(PROYECTO!AE341*(1+PROYECTO!F224+PROYECTO!I224))) -> 0
B16: Mano de Obra | D16: =+(PROYECTO!AK389*PROYECTO!AP389)+(PROYECTO!AK390*PROYECTO!AP390)+(PROYECTO!AK391*PROYECTO!AP391)+(PROYECTO!AK392*PROYECTO!AP392)+(PROYECTO!AK393*PROYECTO!AP393) -> 0 | E16: =+(PROYECTO!AK394*(1+PROYECTO!F224))*12 -> 0 | F16: =+E16*(1+PROYECTO!I224) -> 0
B17: Costos Fijos | D17: =+PROYECTO!AE305 -> 0 | E17: =+D17*(1+PROYECTO!F224) -> 0 | F17: =+(E17*(1+PROYECTO!I224)) -> 0
B18: Permisos y Licencias | D18: =+PROYECTO!Z190 -> 0
B19: Utilidad Bruta | D19: =+D14-D15-D17-D16-D18 -> 0 | E19: =+E14-E15-E17-E16-E18 -> 0 | F19: =+F14-F15-F17-F16-F18 -> 0
B20: Gastos de Administración y Ventas | D20: =+PROYECTO!Y367 -> 0 | E20: =+PROYECTO!AE367 -> 0 | F20: =+PROYECTO!AK367 -> 0
B21: Utilidad Operativa | D21: =+D19-D20 -> 0 | E21: =+E19-E20 -> 0 | F21: =+F19-F20 -> 0
B22: Impuesto de Renta | D22: =+IF($B$12="SI",(D21*0.33),0) -> 0 | E22: =+IF($B$12="SI",(E21*0.33),0) -> 0 | F22: =+IF($B$12="SI",(F21*0.33),0) -> 0
B23: Utilidad Neta Final | D23: =+D21-D22 -> 0 | E23: =+E21-E22 -> 0 | F23: =+F21-F22 -> 0
B25: *Nota: Si su proyecto es individual no le será calculado valor por Impuesto de Renta
B27: FLUJO DE CAJA
B28: Flujo de caja para evaluación | C28: =-'MODELO FINANCIERO'!C5 -> 0 | D28: =+D21 -> 0 | E28: =+E21 -> 0 | F28: =+F21 -> 0
B30: TIR | C30: VALOR PRESENTE NETO
B31: =+IRR(C28:F28) -> #NUM! | C31: =NPV(C8,C28:F28) -> 0

Sheet Hoja2
B3: SI | C3: CC | D3: Aporte Emprendedor
B4: NO | C4: CE | D4: Fondo Emprender
B7: Femenino | F7: Adolescentes en Conflicto con la Ley Penal
B8: Masculino | F8: Adolescente Trabajador
B9: Otro | F9: Adolescentes y Jóvenes Vulnerables
F10: Afrocolombianos
B11: Gestión y Administración | F11: Campesino
B12: Transparencia y Responsabilidad: | F12: Desplazado por fenómenos naturales
B13: Gestión de Recursos | F13: Migrantes que retornan al país
B14: Relaciones con los Miembros y la Comunidad | F14: Mujer cabeza de hogar
B15: Cumplimiento Legal | F15: Negritudes
